<?xml version="1.0" encoding="utf-8"?>
<!-- This URDF was automatically created by SolidWorks to URDF Exporter! Originally created by Stephen Brawner (brawner@gmail.com) 
     Commit Version: 1.4.4-24-g24328f6  Build Version: 1.5.7084.36479
     For more information, please see http://wiki.ros.org/sw_urdf_exporter -->
<robot
  name="compass_gait_walker">
  <link
    name="base_link">
    <inertial>
      <origin
        xyz="0 0 0"
        rpy="0 0 0" />
      <mass
        value="10" />
      <inertia
        ixx="0.0062177"
        ixy="9.035E-20"
        ixz="-3.2627E-52"
        iyy="0.0019635"
        iyz="1.5178E-35"
        izz="0.0062177" />
    </inertial>
    <visual>
      <origin
        xyz="0 0 0"
        rpy="0 0 0" />
      <geometry>
        <mesh
          filename="package://compass_gait_walker/meshes/base_link.STL" />
      </geometry>
      <material
        name="">
        <color
          rgba="0.79216 0.81961 0.93333 1" />
      </material>
    </visual>
    <collision>
      <origin
        xyz="0 0 0"
        rpy="0 0 0" />
      <geometry>
        <mesh
          filename="package://compass_gait_walker/meshes/base_link.STL" />
      </geometry>
    </collision>
  </link>
  <link
    name="right_leg_link">
    <inertial>
      <origin
        xyz="0 1.3878E-17 5.5511E-17"
        rpy="0 0 0" />
      <mass
        value="5" />
      <inertia
        ixx="0.10485"
        ixy="-1.6544E-22"
        ixz="-1.4117E-20"
        iyy="0.10485"
        iyz="-4.5175E-19"
        izz="0.00025133" />
    </inertial>
    <visual>
      <origin
        xyz="0 0 0"
        rpy="0 0 0" />
      <geometry>
        <mesh
          filename="package://compass_gait_walker/meshes/right_leg_link.STL" />
      </geometry>
      <material
        name="">
        <color
          rgba="0.79216 0.81961 0.93333 1" />
      </material>
    </visual>
    <collision>
      <origin
        xyz="0 0 0"
        rpy="0 0 0" />
      <geometry>
        <mesh
          filename="package://compass_gait_walker/meshes/right_leg_link.STL" />
      </geometry>
    </collision>
  </link>
  <joint
    name="right_leg_joint"
    type="revolute">
    <origin
      xyz="0 0.12 -0.5"
      rpy="0 0 0" />
    <parent
      link="base_link" />
    <child
      link="right_leg_link" />
    <axis
      xyz="0 -1 0" />
    <limit
      lower="-1.57"
      upper="1.57"
      effort="100"
      velocity="100" />
    <safety_controller
      k_velocity="0" />
  </joint>
  <link
    name="left_leg_link">
    <inertial>
      <origin
        xyz="0 0 -5.5511E-17"
        rpy="0 0 0" />
      <mass
        value="5" />
      <inertia
        ixx="0.10485"
        ixy="-4.4116E-22"
        ixz="-6.6109E-20"
        iyy="0.10485"
        iyz="3.2693E-18"
        izz="0.00025133" />
    </inertial>
    <visual>
      <origin
        xyz="0 0 0"
        rpy="0 0 0" />
      <geometry>
        <mesh
          filename="package://compass_gait_walker/meshes/left_leg_link.STL" />
      </geometry>
      <material
        name="">
        <color
          rgba="0.79216 0.81961 0.93333 1" />
      </material>
    </visual>
    <collision>
      <origin
        xyz="0 0 0"
        rpy="0 0 0" />
      <geometry>
        <mesh
          filename="package://compass_gait_walker/meshes/left_leg_link.STL" />
      </geometry>
    </collision>
  </link>
  <joint
    name="left_leg_joint"
    type="revolute">
    <origin
      xyz="0 -0.12 -0.5"
      rpy="0 0 0" />
    <parent
      link="base_link" />
    <child
      link="left_leg_link" />
    <axis
      xyz="0 -1 0" />
    <limit
      lower="-1.57"
      upper="1.57"
      effort="100"
      velocity="100" />
    <safety_controller
      k_velocity="0" />
  </joint>
</robot>